from django import forms
from django.contrib.auth.forms import UserCreationForm, AuthenticationForm
from django.contrib.auth.models import User
from django.core.exceptions import ValidationError


class SignUpForm(UserCreationForm):
    username = forms.CharField(label='Логин', widget=forms.TextInput(attrs={'class': 'form-control'}))
    email = forms.EmailField(label='Email', widget=forms.TextInput(attrs={'class': 'form-control'}))
    password1 = forms.CharField(label='Пароль', widget=forms.PasswordInput(attrs={'class': 'form-control'}))
    password2 = forms.CharField(label='Подтверждение пароля', widget=forms.PasswordInput(attrs={'class': 'form-control'}))

    class Meta:
        model = User
        fields = ('username', 'email', 'password1', 'password2')


class SignInForm(AuthenticationForm):
    username = forms.CharField(label='Логин', widget=forms.TextInput(attrs={'class': 'form-control'}))
    password = forms.CharField(label='Пароль', widget=forms.PasswordInput(attrs={'class': 'form-control'}))

    def confirm_login_allowed(self, user):
        if self.request.user.is_authenticated:
            raise ValidationError(
                'Для входа в акканут сначала выйдете из текущего аккаунта',
            )


class AddToCartForm(forms.Form):
    count = forms.IntegerField(label='Количество', min_value=1, widget=forms.NumberInput())


class MakeOrderForm(forms.Form):
    pass
